Workbook

Sheet SUMMARY
A1: Buyer performance scorecard
A2: Sterling Styles Limited · 01 Jan 2026 - 17 Oct 2026 · benchmark $2,500 earned per line per day. Every cell below is a formula reading the tabs behind it.
A4: FACTORY | D4: TOP AND BOTTOM
A5: Line-days | B5: ='BUYER KPI'!C30 -> 8854 | D5: Rank | E5: Buyer | F5: Score
A6: Pieces | B6: ='BUYER KPI'!F30 -> 13465130 | D6: Best score | E6: ZARA | F6: 96.2
A7: Earned $ | B7: ='BUYER KPI'!H30 -> 22647668 | D7: Second | E7: GAP | F7: 94.3
A8: Earned $ per line-day | B8: ='BUYER KPI'!J30 -> 2557.9024 | D8: Third | E8: OJG | F8: 94.2
A9: Vs $2,500 benchmark | B9: ='BUYER KPI'!K30 -> 57.902449 | D9: Lowest score | E9: CARRE FOUR | F9: 60.1
A10: Benchmark hit rate | B10: ='BUYER KPI'!L30 -> 0.5286876 | D10: Second lowest | E10: MED COUTORE | F10: 63.2
A11: Line-days below benchmark | B11: ='BUYER KPI'!M30 -> 4173
A12: CM $ per SMV minute | B12: ='BUYER KPI'!N30 -> 0.08356707 | D12: Buyers below the benchmark | F12: 11
A13: CM $ per piece | B13: ='BUYER KPI'!O30 -> 1.6819494 | D13: Their total period shortfall | F13: 1099689.1
A14: SMV (weighted) | B14: ='BUYER KPI'!P30 -> 20.12694
A15: Efficiency | B15: ='BUYER KPI'!Q30 -> 0.69638952
A16: DHU % | B16: ='BUYER KPI'!R30 -> 0.13167184
A18: HEADLINES
A19: • The factory averages $2,558 per line-day against the $2,500 benchmark, but only 52.9% of individual line-days clear it and 4,173 line-days finished below.
A20: • 11 of the 17 ranked buyers sit under the benchmark on their period average; together they carry a $1,099,689 shortfall in capacity value.
A21: • Efficiency ran 77.0% in 2026-01 against 64.1% at its worst (2026-10), and the benchmark hit rate moved from 61.5% to 45.3%.
A22: • Price per SMV minute stayed inside a 0.0800 - 0.0882 band across the period, so the movement is on the floor, not in the costings.
A23: • At the first month's efficiency the same line-days would have earned roughly $2,402,322 more - compare that to every repricing ask on the improvement plan combined.
A24: • The top three accounts carry 68% of earned value.

Sheet METHOD
A1: How this report and the ranking were built
A2: Plain English. Anyone should be able to check the work or repeat it next month.
A4: THE EIGHT STEPS
A5: 1. Start from the raw daily file | B5: One row per sewing line per day — 8,854 rows, 38 lines, 3 units, 01 Jan 2026 - 17 Oct 2026, read from the "2026" tab of Buyer_wise_average_CM__earned_report-2026__Date.xlsx. The summary tabs in the source workbook average the period and hide the monthly movement, so they are not used.
A6: 2. Fix the CM rate | B6: No costing workbook was supplied for this run, so the CM rate is used exactly as it appears in the daily report. Supply the costing book next time and the affected buyers are repriced automatically.
A7: 3. Rebuild earned value | B7: Earned $ recomputed on every row as pieces × CM. This also corrected 232 rows where the source did not tie.
A8: 4. Roll up to the buyer | B8: Line-days counted; pieces and earned summed; SMV weighted by pieces; efficiency and DHU as the simple mean of daily values (this reproduces the factory yearly figures exactly); run days as the average consecutive days a style holds a line.
A9: 5. Measure against $2,500 | B9: Two views: the average (did the account clear $2,500 per line-day) and the hit rate (what share of its individual line-days actually cleared it). Shortfall = (2,500 − average) × line-days.
A10: 6. Score six standards | B10: Each buyer scored against a fixed factory standard, capped at 100 each, then weighted and summed. No buyer is scored against another buyer, so the scores stay comparable next month even if the buyer mix changes.
A11: 7. Separate small accounts | B11: Under 40 line-days = TRIAL. Scored, listed, but not ranked. A handful of days is not evidence and small samples throw extreme numbers both ways.
A12: 8. Solve for the routes | B12: For each buyer below the benchmark the earning identity is solved backwards three times — for price, for SMV, for efficiency — giving the exact number each lever would have to reach on its own.
A14: THE SIX STANDARDS | B14: Score on each line = actual ÷ standard × 100, capped at 100. Editable on the RANKING tab (yellow cells).
A15: 1. Benchmark achievement — 30% | B15: Standard: $2,500 earned per line per day. The question the factory actually asks: was that line-day worth giving away? Heaviest weight because it already contains price, efficiency and manning inside it.
A16: 2. Value delivered — 20% | B16: Standard: a 10% share of factory earned $. Scale has to count — an account earning $6m cannot rank below one earning $100k on a rate advantage alone.
A17: 3. Price — 20% | B17: Standard: $0.0843 per SMV minute, the factory blended rate. CM per minute is the only fair price comparison; CM per piece across different garments is meaningless.
... A23: Grade bands | B23: A = 85+, B = 75–84, C = 65–74, D = under 65.
A25: DEFINITIONS
A26: Line-day | B26: One sewing line running for one day. The unit of capacity everything is measured in.
A27: Earned $ | B27: Pieces × CM. CM value booked — not FOB, not margin. This workbook can say who earns most per unit of capacity, not who is most profitable.
A28: CM $ per SMV minute | B28: Earned $ ÷ (pieces × SMV). What the buyer pays for one minute of sewing work.
A29: Earned $ per line-day | B29: Capacity yield. What one line earns in one day on that buyer.
A30: Benchmark hit rate | B30: Share of that buyer's individual line-days that earned $2,500 or more.
A31: Efficiency | B31: Simple mean of the daily efficiency values.
A32: DHU % | B32: Defects per hundred units, simple mean of daily values.
A33: SMV (weighted) | B33: Weighted by pieces produced, not a flat average.
A34: Run days | B34: Average consecutive line-days a style holds one line before changeover.
A35: Earning identity | B35: Earned $/line-day = CM$/min × efficiency × operators × working hours × 60.
A37: TABS
A38: SUMMARY | B38: One-page factory scorecard and headlines.
A39: RANKING | B39: The ranking. Standards and weights are yellow and editable; scores, grades and ranks recalculate.
A40: BUYER KPI | B40: Every metric for all 25 buyers. All SUMIFS / AVERAGEIFS over DATA.
A41: BENCHMARK GAP | B41: The $2,500 analysis plus the table of what $2,500 a day requires at each efficiency level.
A42: IMPROVEMENT PLAN | B42: Three routes to the benchmark for every buyer, plus the realistic split route.
A43: MONTHLY TREND | B43: Efficiency, DHU, hit rate, price and yield by month, with charts.
A44: BUYER x MONTH | B44: Earned $ per line-day matrix, colour scaled.
A45: UNIT & LINE | B45: All 3 units and 38 sewing lines against the same benchmark.
A46: DATA | B46: The 8,854-row fact table. Every other tab reads from it. Nothing else is hardcoded.
A48: CAVEATS
A49: Last month may be partial | B49: 2026-10 carries 14 days in this extract. Check before comparing it to a full month.
A50: Missing costings | B50: No costing workbook supplied - CM is exactly as reported in the daily file.
...

Sheet DATA
A1: DATE | B1: MONTH | C1: UNIT | D1: LINE | E1: BUYER | F1: STYLE | G1: STYLE DESCRIPTION | H1: PCS | I1: SMV | J1: SMV MIN | K1: CM $ | L1: EARNED $ | M1: BENCHMARK $ | N1: GAP VS BM $ | O1: HIT (1/0) | P1: EFFICIENCY | Q1: DHU % | R1: OPERATORS | S1: W.HRS
A2: 46023 | B2: 2026-01 | C2: unit-1 | D2: 1 | E2: OJG | F2: 650 | G2: CHINO LONG | H2: 1650 | I2: 22.23 | J2: =H2*I2 -> 36679.5 | K2: 1.51 | L2: =H2*K2 -> 2491.5 | M2: 2500 | N2: =L2-M2 -> -8.5 | O2: =IF(L2>=M2,1,0) -> 0 | P2: 0.8873 | Q2: 0.0965 | R2: 75 | S2: 9
A3: 46023 | B3: 2026-01 | C3: unit-1 | D3: 2 | E3: ZARA | F3: 7147/564 | G3: KIDS-A DENIM VESTIDO CUELLO ONDULINA CASUAL 1 MARZO | H3: 1700 | I3: 13.75 | J3: =H3*I3 -> 23375 | K3: 1.55 | L3: =H3*K3 -> 2635 | M3: 2500 | N3: =L3-M3 -> 135 | O3: =IF(L3>=M3,1,0) -> 1 | P3: 0.6012 | Q3: 0.0576 | R3: 64 | S3: 9
A4: 46023 | B4: 2026-01 | C4: unit-1 | D4: 3 | E4: ZARA | F4: 7147/029 | G4: B- DNM WIDE LEG MID RISE CON PINZAS | H4: 1550 | I4: 20.32 | J4: =H4*I4 -> 31496 | K4: 1.75 | L4: =H4*K4 -> 2712.5 | M4: 2500 | N4: =L4-M4 -> 212.5 | O4: =IF(L4>=M4,1,0) -> 1 | P4: 0.8027 | Q4: 0.1451 | R4: 67 | S4: 10
A5: 46023 | B5: 2026-01 | C5: unit-1 | D5: 4 | E5: EXPRESS | F5: 9113299 | G5: HR WIDE LEG ANKLE | H5: 1500 | I5: 21.09 | J5: =H5*I5 -> 31635 | K5: 3 | L5: =H5*K5 -> 4500 | M5: 2500 | N5: =L5-M5 -> 2000 | O5: =IF(L5>=M5,1,0) -> 1 | P5: 0.7458 | Q5: 0.0865 | R5: 73 | S5: 10
A6: 46023 | B6: 2026-01 | C6: unit-1 | D6: 5 | E6: GAP | F6: 805650 | G6: BASIC 5 POCKET PANT | H6: 1500 | I6: 21.36 | J6: =H6*I6 -> 32040 | K6: 2.2 | L6: =H6*K6 -> 3300 | M6: 2500 | N6: =L6-M6 -> 800 | O6: =IF(L6>=M6,1,0) -> 1 | P6: 0.7717 | Q6: 0.1415 | R6: 75 | S6: 9
A7: 46023 | B7: 2026-01 | C7: unit-1 | D7: 6 | E7: ZARA | F7: 7147/564 | G7: KIDS-A DENIM VESTIDO CUELLO ONDULINA CASUAL 1 MARZO | H7: 600 | I7: 13.75 | J7: =H7*I7 -> 8250 | K7: 1.55 | L7: =H7*K7 -> 930 | M7: 2500 | N7: =L7-M7 -> -1570 | O7: =IF(L7>=M7,1,0) -> 0 | P7: 0.2795 | Q7: 0.1953 | R7: 58 | S7: 9
A8: 46023 | B8: 2026-01 | C8: unit-1 | D8: 7 | E8: GAP | F8: 788041 | G8: BASIC 5 POCKET PANT | H8: 1650 | I8: 20.43 | J8: =H8*I8 -> 33709.5 | K8: 2.2 | L8: =H8*K8 -> 3630 | M8: 2500 | N8: =L8-M8 -> 1130 | O8: =IF(L8>=M8,1,0) -> 1 | P8: 0.8348 | Q8: 0.1232 | R8: 74 | S8: 9
A9: 46023 | B9: 2026-01 | C9: unit-1 | D9: 8 | E9: GAP | F9: 1172653 | G9: BASIC 5 POCKET PANT | H9: 1800 | I9: 19.64 | J9: =H9*I9 -> 35352 | K9: 2.2 | L9: =H9*K9 -> 3960 | M9: 2500 | N9: =L9-M9 -> 1460 | O9: =IF(L9>=M9,1,0) -> 1 | P9: 0.7877 | Q9: 0.1208 | R9: 74 | S9: 10
A10: 46023 | B10: 2026-01 | C10: unit-1 | D10: 9 | E10: LAGER | F10: GIANT | G10: MEN'S 5 PKT JEAN | H10: 1500 | I10: 21.68 | J10: =H10*I10 -> 32520 | K10: 1.5 | L10: =H10*K10 -> 2250 | M10: 2500 | N10: =L10-M10 -> -250 | O10: =IF(L10>=M10,1,0) -> 0 | P10: 0.7688 | Q10: 0.1111 | R10: 72 | S10: 10
A11: 46023 | B11: 2026-01 | C11: unit-1 | D11: 10 | E11: ZARA | F11: 7147/602 | G11: STER-S2606. PANT FLUIDO ALGODÓN | H11: 1750 | I11: 19.34 | J11: =H11*I11 -> 33845 | K11: 1.44 | L11: =H11*K11 -> 2520 | M11: 2500 | N11: =L11-M11 -> 20 | O11: =IF(L11>=M11,1,0) -> 1 | P11: 0.8786 | Q11: 0.1096 | R11: 65 | S11: 10
A12: 46023 | B12: 2026-01 | C12: unit-1 | D12: 11 | E12: ZARA | F12: 7147/563 | G12: STER-S2606. PANT FLUIDO ALGODÓN | H12: 1800 | I12: 19.34 | J12: =H12*I12 -> 34812 | K12: 1.44 | L12: =H12*K12 -> 2592 | M12: 2500 | N12: =L12-M12 -> 92 | O12: =IF(L12>=M12,1,0) -> 1 | P12: 0.8218 | Q12: 0.1056 | R12: 68 | S12: 10
A13: 46023 | B13: 2026-01 | C13: unit-1 | D13: 12 | E13: ZARA | F13: 7147/507 | G13: KIDSA DENIM PANTALON CULOTTE COMFY CRUDO E.PAISES | H13: 2400 | I13: 16.51 | J13: =H13*I13 -> 39624 | K13: 1.52 | L13: =H13*K13 -> 3648 | M13: 2500 | N13: =L13-M13 -> 1148 | O13: =IF(L13>=M13,1,0) -> 1 | P13: 0.8888 | Q13: 0.1015 | R13: 73 | S13: 10
... A5976: 46223 | B5976: 2026-07 | C5976: unit-1 | D5976: 9 | E5976: OJG | F5976: WPJSB-15464 | G5976: ZINNIA WIDE LEG BOYFRIEND | H5976: 1150 | I5976: 18.43 | J5976: =H5976*I5976 -> 21194.5 | K5976: 1.45 | L5976: =H5976*K5976 -> 1667.5 | M5976: 2500 | N5976: =L5976-M5976 -> -832.5 | O5976: =IF(L5976>=M5976,1,0) -> 0 | P5976: 0.4127 | Q5976: 0.12 | R5976: 72 | S5976: 13
A5977: 46223 | B5977: 2026-07 | C5977: unit-1 | D5977: 10 | E5977: NEXT | F5977: G86107 | H5977: 1700 | I5977: 10.96 | J5977: =H5977*I5977 -> 18632 | K5977: 1 | L5977: =H5977*K5977 -> 1700 | M5977: 2500 | N5977: =L5977-M5977 -> -800 | O5977: =IF(L5977>=M5977,1,0) -> 0 | P5977: 0.4921 | Q5977: 0.1 | R5977: 61 | S5977: 10
A5978: 46223 | B5978: 2026-07 | C5978: unit-1 | D5978: 11 | E5978: ZARA | F5978: 7147/436 | G5978: G.A SEMI JOGGER RUSTICO | H5978: 1550 | I5978: 22.05 | J5978: =H5978*I5978 -> 34177.5 | K5978: 1.83 | L5978: =H5978*K5978 -> 2836.5 | M5978: 2500 | N5978: =L5978-M5978 -> 336.5 | O5978: =IF(L5978>=M5978,1,0) -> 1 | P5978: 0.6981 | Q5978: 0.2 | R5978: 80 | S5978: 10
A5979: 46223 | B5979: 2026-07 | C5979: unit-1 | D5979: 12 | E5979: SOLAMODA | F5979: 4387/493 | G5979: Chino Pant | H5979: 1400 | I5979: 24.08 | J5979: =H5979*I5979 -> 33712 | K5979: 1.55 | L5979: =H5979*K5979 -> 2170 | M5979: 2500 | N5979: =L5979-M5979 -> -330 | O5979: =IF(L5979>=M5979,1,0) -> 0 | P5979: 0.6894 | Q5979: 0.1026 | R5979: 79 | S5979: 10
A5980: 46223 | B5980: 2026-07 | C5980: unit-1 | D5980: 13 | E5980: OJG | F5980: 1627 | G5980: RLXD BF SHIRT | H5980: 1200 | I5980: 25.7 | J5980: =H5980*I5980 -> 30840 | K5980: 1.85 | L5980: =H5980*K5980 -> 2220 | M5980: 2500 | N5980: =L5980-M5980 -> -280 | O5980: =IF(L5980>=M5980,1,0) -> 0 | P5980: 0.7859 | Q5980: 0.1329 | R5980: 78 | S5980: 8
A5981: 46223 | B5981: 2026-07 | C5981: unit-1 | D5981: 14 | E5981: ZARA | F5981: 7147/450 | G5981: G.A. PANTALON ARCADE ORIGINAL | H5981: 1300 | I5981: 28.66 | J5981: =H5981*I5981 -> 37258 | K5981: 2.3 | L5981: =H5981*K5981 -> 2990 | M5981: 2500 | N5981: =L5981-M5981 -> 490 | O5981: =IF(L5981>=M5981,1,0) -> 1 | P5981: 0.7482 | Q5981: 0.35 | R5981: 80 | S5981: 10
A5982: 46223 | B5982: 2026-07 | C5982: unit-1 | D5982: 15 | E5982: ZARA | F5982: 7147/450 | G5982: G.A. PANTALON ARCADE ORIGINAL | H5982: 1300 | I5982: 28.66 | J5982: =H5982*I5982 -> 37258 | K5982: 2.3 | L5982: =H5982*K5982 -> 2990 | M5982: 2500 | N5982: =L5982-M5982 -> 490 | O5982: =IF(L5982>=M5982,1,0) -> 1 | P5982: 0.7482 | Q5982: 0.312 | R5982: 80 | S5982: 10
A5983: 46223 | B5983: 2026-07 | C5983: unit-1 | D5983: 16 | E5983: ZARA | F5983: 7147/550 | G5983: KIDS-O DENIM PANT BAGGY 4L | H5983: 1700 | I5983: 18.5 | J5983: =H5983*I5983 -> 31450 | K5983: 1.4 | L5983: =H5983*K5983 -> 2380 | M5983: 2500 | N5983: =L5983-M5983 -> -120 | O5983: =IF(L5983>=M5983,1,0) -> 0 | P5983: 0.8064 | Q5983: 0.154 | R5983: 65 | S5983: 10
A5984: 46223 | B5984: 2026-07 | C5984: unit-2 | D5984: 17 | E5984: SOLAMODA | F5984: 4387/493 | G5984: Chino Pant | H5984: 1500 | I5984: 24.08 | J5984: =H5984*I5984 -> 36120 | K5984: 1.55 | L5984: =H5984*K5984 -> 2325 | M5984: 2500 | N5984: =L5984-M5984 -> -175 | O5984: =IF(L5984>=M5984,1,0) -> 0 | P5984: 0.7478 | Q5984: 0.0976 | R5984: 79 | S5984: 10
A5985: 46223 | B5985: 2026-07 | C5985: unit-2 | D5985: 18 | E5985: KMART | F5985: PA457 | G5985: PLEATED SHORT | H5985: 1700 | I5985: 20.81 | J5985: =H5985*I5985 -> 35377 | K5985: 1.5 | L5985: =H5985*K5985 -> 2550 | M5985: 2500 | N5985: =L5985-M5985 -> 50 | O5985: =IF(L5985>=M5985,1,0) -> 1 | P5985: 0.6824 | Q5985: 0.0835 | R5985: 81 | S5985: 10
A5986: 46223 | B5986: 2026-07 | C5986: unit-2 | D5986: 19 | E5986: TARGET | F5986: 2900331277 | G5986: BARREL 5 POCKET | H5986: 1000 | I5986: 25.7 | J5986: =H5986*I5986 -> 25700 | K5986: 1.93 | L5986: =H5986*K5986 -> 1930 | M5986: 2500 | N5986: =L5986-M5986 -> -570 | O5986: =IF(L5986>=M5986,1,0) -> 0 | P5986: 0.5548 | Q5986: 0.0831 | R5986: 78 | S5986: 10
A5987: 46223 | B5987: 2026-07 | C5987: unit-2 | D5987: 20 | E5987: OJG | F5987: 1627 | G5987: RLXD BF SHIRT | H5987: 1600 | I5987: 25.7 | J5987: =H5987*I5987 -> 41120 | K5987: 1.85 | L5987: =H5987*K5987 -> 2960 | M5987: 2500 | N5987: =L5987-M5987 -> 460 | O5987: =IF(L5987>=M5987,1,0) -> 1 | P5987: 0.7997 | Q5987: 0.0957 | R5987: 81 | S5987: 10
A5988: 46223 | B5988: 2026-07 | C5988: unit-2 | D5988: 21 | E5988: ZARA | F5988: 7147/233 | G5988: B - DNIM JACKET CUELLO COMBINADO | H5988: 900 | I5988: 49.25 | J5988: =H5988*I5988 -> 44325 | K5988: 4 | L5988: =H5988*K5988 -> 3600 | M5988: 2500 | N5988: =L5988-M5988 -> 1100 | O5988: =IF(L5988>=M5988,1,0) -> 1 | P5988: 0.7322 | Q5988: 0.1496 | R5988: 79 | S5988: 13
A5989: 46223 | B5989: 2026-07 | C5989: unit-2 | D5989: 22 | E5989: ZARA | F5989: 7147/450 | G5989: B- DNM WIDE LEG PINZAS TRASPASO CINTURA SET | H5989: 1300 | I5989: 28.66 | J5989: =H5989*I5989 -> 37258 | K5989: 2.3 | L5989: =H5989*K5989 -> 2990 | M5989: 2500 | N5989: =L5989-M5989 -> 490 | O5989: =IF(L5989>=M5989,1,0) -> 1 | P5989: 0.7357 | Q5989: 0.1146 | R5989: 84 | S5989: 10
... A8660: 46306 | B8660: 2026-10 | C8660: unit-3 | D8660: 33 | E8660: TRIBAL | F8660: 61190 | G8660: 5 PKT LONG PANT | H8660: 1350 | I8660: 18.72 | J8660: =H8660*I8660 -> 25272 | K8660: 2.5 | L8660: =H8660*K8660 -> 3375 | M8660: 2500 | N8660: =L8660-M8660 -> 875 | O8660: =IF(L8660>=M8660,1,0) -> 1 | P8660: 0.54313346 | Q8660: 0.14185111 | R8660: 71 | S8660: 13
A8661: 46306 | B8661: 2026-10 | C8661: unit-3 | D8661: 34 | E8661: AERO | F8661: 7155 | G8661: INNER MAKE | H8661: 5730 | I8661: 3.83 | J8661: =H8661*I8661 -> 21945.9 | K8661: 0 | L8661: =H8661*K8661 -> 0 | M8661: 2500 | N8661: =L8661-M8661 -> -2500 | O8661: =IF(L8661>=M8661,1,0) -> 0 | P8661: 0.74841479 | R8661: 70 | S8661: 13
A8662: 46306 | B8662: 2026-10 | C8662: unit-3 | D8662: 35 | E8662: CARRE FOUR | F8662: 10449 | G8662: CASH PANT | H8662: 1420 | I8662: 20.33 | J8662: =H8662*I8662 -> 28868.6 | K8662: 1.55 | L8662: =H8662*K8662 -> 2201 | M8662: 2500 | N8662: =L8662-M8662 -> -299 | O8662: =IF(L8662>=M8662,1,0) -> 0 | P8662: 0.60904219 | Q8662: 0.1387931 | R8662: 55 | S8662: 13
A8663: 46306 | B8663: 2026-10 | C8663: unit-3 | D8663: 36 | E8663: AERO | F8663: 7100 | G8663: MICRO SKIRT | H8663: 800 | I8663: 21.74 | J8663: =H8663*I8663 -> 17392 | K8663: 2.2 | L8663: =H8663*K8663 -> 1760 | M8663: 2500 | N8663: =L8663-M8663 -> -740 | O8663: =IF(L8663>=M8663,1,0) -> 0 | P8663: 0.37762996 | Q8663: 0.12359551 | R8663: 67 | S8663: 13
A8664: 46306 | B8664: 2026-10 | C8664: unit-3 | D8664: 37 | E8664: AERO | F8664: 6000 | G8664: 5 PKT LONG PANT | H8664: 1350 | I8664: 20.16 | J8664: =H8664*I8664 -> 27216 | K8664: 2.45 | L8664: =H8664*K8664 -> 3307.5 | M8664: 2500 | N8664: =L8664-M8664 -> 807.5 | O8664: =IF(L8664>=M8664,1,0) -> 1 | P8664: 0.59371728 | Q8664: 0.15021459 | R8664: 75 | S8664: 13
A8665: 46306 | B8665: 2026-10 | C8665: unit-3 | D8665: 38 | E8665: CARRE FOUR | F8665: 10451 | G8665: CARGO LONG PANT | H8665: 1000 | I8665: 27.97 | J8665: =H8665*I8665 -> 27970 | K8665: 2.15 | L8665: =H8665*K8665 -> 2150 | M8665: 2500 | N8665: =L8665-M8665 -> -350 | O8665: =IF(L8665>=M8665,1,0) -> 0 | P8665: 0.54843137 | Q8665: 0.093301435 | R8665: 82 | S8665: 13
A8666: 46307 | B8666: 2026-10 | C8666: unit-1 | D8666: 1 | E8666: GAP | F8666: 1200301 | G8666: BASIC 5 POCKET PANT | H8666: 282 | I8666: 19.8 | J8666: =H8666*I8666 -> 5583.6 | K8666: 2.2 | L8666: =H8666*K8666 -> 620.4 | M8666: 2500 | N8666: =L8666-M8666 -> -1879.6 | O8666: =IF(L8666>=M8666,1,0) -> 0 | P8666: 0.1445 | Q8666: 0.3846 | R8666: 73 | S8666: 8
A8667: 46307 | B8667: 2026-10 | C8667: unit-1 | D8667: 2 | E8667: OJG | F8667: 3185 | G8667: MID RISE WIDE LEG | H8667: 1660 | I8667: 19.14 | J8667: =H8667*I8667 -> 31772.4 | K8667: 1.33 | L8667: =H8667*K8667 -> 2207.8 | M8667: 2500 | N8667: =L8667-M8667 -> -292.2 | O8667: =IF(L8667>=M8667,1,0) -> 0 | P8667: 0.6201 | Q8667: 0.1005 | R8667: 70 | S8667: 13
A8668: 46307 | B8668: 2026-10 | C8668: unit-1 | D8668: 3 | E8668: NEW YORKER | F8668: 20393 | G8668: FLARED FB | H8668: 1900 | I8668: 20.91 | J8668: =H8668*I8668 -> 39729 | K8668: 1.46 | L8668: =H8668*K8668 -> 2774 | M8668: 2500 | N8668: =L8668-M8668 -> 274 | O8668: =IF(L8668>=M8668,1,0) -> 1 | P8668: 0.6977 | Q8668: 0.0764 | R8668: 76 | S8668: 13
A8669: 46307 | B8669: 2026-10 | C8669: unit-1 | D8669: 4 | E8669: EXPRESS | F8669: 2410192 | G8669: Straight Douglass | H8669: 1820 | I8669: 20.62 | J8669: =H8669*I8669 -> 37528.4 | K8669: 2.2 | L8669: =H8669*K8669 -> 4004 | M8669: 2500 | N8669: =L8669-M8669 -> 1504 | O8669: =IF(L8669>=M8669,1,0) -> 1 | P8669: 0.7333 | Q8669: 0.0816 | R8669: 74 | S8669: 12
A8670: 46307 | B8670: 2026-10 | C8670: unit-1 | D8670: 5 | E8670: GAP | F8670: 807350 | G8670: BASIC 5 POCKET PANT | H8670: 1710 | I8670: 17.37 | J8670: =H8670*I8670 -> 29702.7 | K8670: 2.2 | L8670: =H8670*K8670 -> 3762 | M8670: 2500 | N8670: =L8670-M8670 -> 1262 | O8670: =IF(L8670>=M8670,1,0) -> 1 | P8670: 0.595 | Q8670: 0.1342 | R8670: 70 | S8670: 12
A8671: 46307 | B8671: 2026-10 | C8671: unit-1 | D8671: 6 | E8671: OJG | F8671: 2692 | G8671: 5 Pkt long pant | H8671: 2000 | I8671: 16.96 | J8671: =H8671*I8671 -> 33920 | K8671: 1.4 | L8671: =H8671*K8671 -> 2800 | M8671: 2500 | N8671: =L8671-M8671 -> 300 | O8671: =IF(L8671>=M8671,1,0) -> 1 | P8671: 0.7498 | Q8671: 0.1194 | R8671: 64 | S8671: 12
A8672: 46307 | B8672: 2026-10 | C8672: unit-1 | D8672: 7 | E8672: GAP | F8672: 867846 | G8672: BASIC 5 POCKET PANT | H8672: 2250 | I8672: 15.11 | J8672: =H8672*I8672 -> 33997.5 | K8672: 2.2 | L8672: =H8672*K8672 -> 4950 | M8672: 2500 | N8672: =L8672-M8672 -> 2450 | O8672: =IF(L8672>=M8672,1,0) -> 1 | P8672: 0.7349 | Q8672: 0.1 | R8672: 65 | S8672: 12
...

Sheet BUYER KPI
A1: Buyer KPI — all buyers, 01 Jan 2026 - 17 Oct 2026
A2: Every figure is a COUNTIFS / SUMIFS / AVERAGEIFS over the DATA tab. Blue text = value computed from the line-day sequence (run days, changeovers).
A4: BUYER | B4: TIER | C4: LINE-DAYS | D4: LINES | E4: STYLES | F4: PIECES | G4: PCS / LINE-DAY | H4: EARNED $ | I4: SHARE % | J4: EARNED $ / LINE-DAY | K4: VS $2,500 | L4: HIT RATE | M4: DAYS BELOW | N4: CM $/SMV MIN | O4: CM $ / PC | P4: SMV (WTD) | Q4: EFFICIENCY | R4: DHU % | S4: RUN DAYS | T4: OPERATORS | U4: W.HRS
A5: ZARA | B5: RANKED | C5: =COUNTIFS(DATA!$E$2:$E$8855,$A5) -> 2451 | D5: 27 | E5: 82 | F5: =SUMIFS(DATA!$H$2:$H$8855,DATA!$E$2:$E$8855,$A5) -> 3761333 | G5: =IFERROR(F5/C5,0) -> 1534.6116 | H5: =SUMIFS(DATA!$L$2:$L$8855,DATA!$E$2:$E$8855,$A5) -> 7120480 | I5: =H5/SUM($H$5:$H$29) -> 0.31440234 | J5: =IFERROR(H5/C5,0) -> 2905.1326 | K5: =J5-2500 -> 405.13258 | L5: =IFERROR(SUMIFS(DATA!$O$2:$O$8855,DATA!$E$2:$E$8855,$A5)/C5,0) -> 0.73602611 | M5: =C5-SUMIFS(DATA!$O$2:$O$8855,DATA!$E$2:$E$8855,$A5) -> 647 | N5: =IFERROR(H5/SUMIFS(DATA!$J$2:$J$8855,DATA!$E$2:$E$8855,$A5),0) -> 0.087361825 | O5: =IFERROR(H5/F5,0) -> 1.8930735 | P5: =IFERROR(SUMIFS(DATA!$J$2:$J$8855,DATA!$E$2:$E$8855,$A5)/F5,0) -> 21.669345 | Q5: =IFERROR(AVERAGEIFS(DATA!$P$2:$P$8855,DATA!$E$2:$E$8855,$A5),0) -> 0.74457829 | R5: =IFERROR(AVERAGEIFS(DATA!$Q$2:$Q$8855,DATA!$E$2:$E$8855,$A5),0) -> 0.13826704 | S5: 10.94 | T5: =IFERROR(AVERAGEIFS(DATA!$R$2:$R$8855,DATA!$E$2:$E$8855,$A5),0) -> 74.709098 | U5: =IFERROR(AVERAGEIFS(DATA!$S$2:$S$8855,DATA!$E$2:$E$8855,$A5),0) -> 10.214606
A6: GAP | B6: RANKED | C6: =COUNTIFS(DATA!$E$2:$E$8855,$A6) -> 737 | D6: 8 | E6: 47 | F6: =SUMIFS(DATA!$H$2:$H$8855,DATA!$E$2:$E$8855,$A6) -> 1226602 | G6: =IFERROR(F6/C6,0) -> 1664.3175 | H6: =SUMIFS(DATA!$L$2:$L$8855,DATA!$E$2:$E$8855,$A6) -> 2300232.4 | I6: =H6/SUM($H$5:$H$29) -> 0.10156597 | J6: =IFERROR(H6/C6,0) -> 3121.0752 | K6: =J6-2500 -> 621.07517 | L6: =IFERROR(SUMIFS(DATA!$O$2:$O$8855,DATA!$E$2:$E$8855,$A6)/C6,0) -> 0.79104478 | M6: =C6-SUMIFS(DATA!$O$2:$O$8855,DATA!$E$2:$E$8855,$A6) -> 154 | N6: =IFERROR(H6/SUMIFS(DATA!$J$2:$J$8855,DATA!$E$2:$E$8855,$A6),0) -> 0.098573888 | O6: =IFERROR(H6/F6,0) -> 1.8752883 | P6: =IFERROR(SUMIFS(DATA!$J$2:$J$8855,DATA!$E$2:$E$8855,$A6)/F6,0) -> 19.024189 | Q6: =IFERROR(AVERAGEIFS(DATA!$P$2:$P$8855,DATA!$E$2:$E$8855,$A6),0) -> 0.74508733 | R6: =IFERROR(AVERAGEIFS(DATA!$Q$2:$Q$8855,DATA!$E$2:$E$8855,$A6),0) -> 0.12840963 | S6: 5.15 | T6: =IFERROR(AVERAGEIFS(DATA!$R$2:$R$8855,DATA!$E$2:$E$8855,$A6),0) -> 72.864315 | U6: =IFERROR(AVERAGEIFS(DATA!$S$2:$S$8855,DATA!$E$2:$E$8855,$A6),0) -> 9.7951153
A7: OJG | B7: RANKED | C7: =COUNTIFS(DATA!$E$2:$E$8855,$A7) -> 2515 | D7: 36 | E7: 67 | F7: =SUMIFS(DATA!$H$2:$H$8855,DATA!$E$2:$E$8855,$A7) -> 3983582.5 | G7: =IFERROR(F7/C7,0) -> 1583.9294 | H7: =SUMIFS(DATA!$L$2:$L$8855,DATA!$E$2:$E$8855,$A7) -> 6082386.7 | I7: =H7/SUM($H$5:$H$29) -> 0.26856569 | J7: =IFERROR(H7/C7,0) -> 2418.444 | K7: =J7-2500 -> -81.555977 | L7: =IFERROR(SUMIFS(DATA!$O$2:$O$8855,DATA!$E$2:$E$8855,$A7)/C7,0) -> 0.49105368 | M7: =C7-SUMIFS(DATA!$O$2:$O$8855,DATA!$E$2:$E$8855,$A7) -> 1280 | N7: =IFERROR(H7/SUMIFS(DATA!$J$2:$J$8855,DATA!$E$2:$E$8855,$A7),0) -> 0.079700162 | O7: =IFERROR(H7/F7,0) -> 1.5268635 | P7: =IFERROR(SUMIFS(DATA!$J$2:$J$8855,DATA!$E$2:$E$8855,$A7)/F7,0) -> 19.157596 | Q7: =IFERROR(AVERAGEIFS(DATA!$P$2:$P$8855,DATA!$E$2:$E$8855,$A7),0) -> 0.70269445 | R7: =IFERROR(AVERAGEIFS(DATA!$Q$2:$Q$8855,DATA!$E$2:$E$8855,$A7),0) -> 0.12356669 | S7: 9.94 | T7: =IFERROR(AVERAGEIFS(DATA!$R$2:$R$8855,DATA!$E$2:$E$8855,$A7),0) -> 73.71332 | U7: =IFERROR(AVERAGEIFS(DATA!$S$2:$S$8855,DATA!$E$2:$E$8855,$A7),0) -> 10.140437
A8: TARGET | B8: RANKED | C8: =COUNTIFS(DATA!$E$2:$E$8855,$A8) -> 596 | D8: 12 | E8: 96 | F8: =SUMIFS(DATA!$H$2:$H$8855,DATA!$E$2:$E$8855,$A8) -> 798071 | G8: =IFERROR(F8/C8,0) -> 1339.0453 | H8: =SUMIFS(DATA!$L$2:$L$8855,DATA!$E$2:$E$8855,$A8) -> 1313095.2 | I8: =H8/SUM($H$5:$H$29) -> 0.057979267 | J8: =IFERROR(H8/C8,0) -> 2203.1799 | K8: =J8-2500 -> -296.82013 | L8: =IFERROR(SUMIFS(DATA!$O$2:$O$8855,DATA!$E$2:$E$8855,$A8)/C8,0) -> 0.31040268 | M8: =C8-SUMIFS(DATA!$O$2:$O$8855,DATA!$E$2:$E$8855,$A8) -> 411 | N8: =IFERROR(H8/SUMIFS(DATA!$J$2:$J$8855,DATA!$E$2:$E$8855,$A8),0) -> 0.075825716 | O8: =IFERROR(H8/F8,0) -> 1.6453363 | P8: =IFERROR(SUMIFS(DATA!$J$2:$J$8855,DATA!$E$2:$E$8855,$A8)/F8,0) -> 21.698922 | Q8: =IFERROR(AVERAGEIFS(DATA!$P$2:$P$8855,DATA!$E$2:$E$8855,$A8),0) -> 0.66951562 | R8: =IFERROR(AVERAGEIFS(DATA!$Q$2:$Q$8855,DATA!$E$2:$E$8855,$A8),0) -> 0.11709338 | S8: 2.77 | T8: =IFERROR(AVERAGEIFS(DATA!$R$2:$R$8855,DATA!$E$2:$E$8855,$A8),0) -> 72.765101 | U8: =IFERROR(AVERAGEIFS(DATA!$S$2:$S$8855,DATA!$E$2:$E$8855,$A8),0) -> 10.258389
A9: EXPRESS | B9: RANKED | C9: =COUNTIFS(DATA!$E$2:$E$8855,$A9) -> 258 | D9: 4 | E9: 57 | F9: =SUMIFS(DATA!$H$2:$H$8855,DATA!$E$2:$E$8855,$A9) -> 328275 | G9: =IFERROR(F9/C9,0) -> 1272.3837 | H9: =SUMIFS(DATA!$L$2:$L$8855,DATA!$E$2:$E$8855,$A9) -> 807715.5 | I9: =H9/SUM($H$5:$H$29) -> 0.0356644 | J9: =IFERROR(H9/C9,0) -> 3130.6802 | K9: =J9-2500 -> 630.68023 | L9: =IFERROR(SUMIFS(DATA!$O$2:$O$8855,DATA!$E$2:$E$8855,$A9)/C9,0) -> 0.7751938 | M9: =C9-SUMIFS(DATA!$O$2:$O$8855,DATA!$E$2:$E$8855,$A9) -> 58 | N9: =IFERROR(H9/SUMIFS(DATA!$J$2:$J$8855,DATA!$E$2:$E$8855,$A9),0) -> 0.11590567 | O9: =IFERROR(H9/F9,0) -> 2.4604844 | P9: =IFERROR(SUMIFS(DATA!$J$2:$J$8855,DATA!$E$2:$E$8855,$A9)/F9,0) -> 21.228334 | Q9: =IFERROR(AVERAGEIFS(DATA!$P$2:$P$8855,DATA!$E$2:$E$8855,$A9),0) -> 0.64701564 | R9: =IFERROR(AVERAGEIFS(DATA!$Q$2:$Q$8855,DATA!$E$2:$E$8855,$A9),0) -> 0.14220599 | S9: 2.3 | T9: =IFERROR(AVERAGEIFS(DATA!$R$2:$R$8855,DATA!$E$2:$E$8855,$A9),0) -> 74.705426 | U9: =IFERROR(AVERAGEIFS(DATA!$S$2:$S$8855,DATA!$E$2:$E$8855,$A9),0) -> 9.3178295
A10: AERO | B10: RANKED | C10: =COUNTIFS(DATA!$E$2:$E$8855,$A10) -> 140 | D10: 9 | E10: 8 | F10: =SUMIFS(DATA!$H$2:$H$8855,DATA!$E$2:$E$8855,$A10) -> 219914 | G10: =IFERROR(F10/C10,0) -> 1570.8143 | H10: =SUMIFS(DATA!$L$2:$L$8855,DATA!$E$2:$E$8855,$A10) -> 357181.6 | I10: =H10/SUM($H$5:$H$29) -> 0.015771231 | J10: =IFERROR(H10/C10,0) -> 2551.2971 | K10: =J10-2500 -> 51.297143 | L10: =IFERROR(SUMIFS(DATA!$O$2:$O$8855,DATA!$E$2:$E$8855,$A10)/C10,0) -> 0.64285714 | M10: =C10-SUMIFS(DATA!$O$2:$O$8855,DATA!$E$2:$E$8855,$A10) -> 50 | N10: =IFERROR(H10/SUMIFS(DATA!$J$2:$J$8855,DATA!$E$2:$E$8855,$A10),0) -> 0.097944429 | O10: =IFERROR(H10/F10,0) -> 1.6241876 | P10: =IFERROR(SUMIFS(DATA!$J$2:$J$8855,DATA!$E$2:$E$8855,$A10)/F10,0) -> 16.582746 | Q10: =IFERROR(AVERAGEIFS(DATA!$P$2:$P$8855,DATA!$E$2:$E$8855,$A10),0) -> 0.62616115 | R10: =IFERROR(AVERAGEIFS(DATA!$Q$2:$Q$8855,DATA!$E$2:$E$8855,$A10),0) -> 0.12770831 | S10: 7.37 | T10: =IFERROR(AVERAGEIFS(DATA!$R$2:$R$8855,DATA!$E$2:$E$8855,$A10),0) -> 71.757143 | U10: =IFERROR(AVERAGEIFS(DATA!$S$2:$S$8855,DATA!$E$2:$E$8855,$A10),0) -> 10.136643
A11: IMPLUSE | B11: RANKED | C11: =COUNTIFS(DATA!$E$2:$E$8855,$A11) -> 180 | D11: 6 | E11: 10 | F11: =SUMIFS(DATA!$H$2:$H$8855,DATA!$E$2:$E$8855,$A11) -> 252030 | G11: =IFERROR(F11/C11,0) -> 1400.1667 | H11: =SUMIFS(DATA!$L$2:$L$8855,DATA!$E$2:$E$8855,$A11) -> 412264 | I11: =H11/SUM($H$5:$H$29) -> 0.018203375 | J11: =IFERROR(H11/C11,0) -> 2290.3556 | K11: =J11-2500 -> -209.64444 | L11: =IFERROR(SUMIFS(DATA!$O$2:$O$8855,DATA!$E$2:$E$8855,$A11)/C11,0) -> 0.48888889 | M11: =C11-SUMIFS(DATA!$O$2:$O$8855,DATA!$E$2:$E$8855,$A11) -> 92 | N11: =IFERROR(H11/SUMIFS(DATA!$J$2:$J$8855,DATA!$E$2:$E$8855,$A11),0) -> 0.08127649 | O11: =IFERROR(H11/F11,0) -> 1.6357735 | P11: =IFERROR(SUMIFS(DATA!$J$2:$J$8855,DATA!$E$2:$E$8855,$A11)/F11,0) -> 20.126035 | Q11: =IFERROR(AVERAGEIFS(DATA!$P$2:$P$8855,DATA!$E$2:$E$8855,$A11),0) -> 0.62849872 | R11: =IFERROR(AVERAGEIFS(DATA!$Q$2:$Q$8855,DATA!$E$2:$E$8855,$A11),0) -> 0.10862133 | S11: 8.57 | T11: =IFERROR(AVERAGEIFS(DATA!$R$2:$R$8855,DATA!$E$2:$E$8855,$A11),0) -> 75.372222 | U11: =IFERROR(AVERAGEIFS(DATA!$S$2:$S$8855,DATA!$E$2:$E$8855,$A11),0) -> 10.011111
A12: SOLAMODA | B12: RANKED | C12: =COUNTIFS(DATA!$E$2:$E$8855,$A12) -> 354 | D12: 10 | E12: 18 | F12: =SUMIFS(DATA!$H$2:$H$8855,DATA!$E$2:$E$8855,$A12) -> 499190 | G12: =IFERROR(F12/C12,0) -> 1410.1412 | H12: =SUMIFS(DATA!$L$2:$L$8855,DATA!$E$2:$E$8855,$A12) -> 779521.4 | I12: =H12/SUM($H$5:$H$29) -> 0.034419499 | J12: =IFERROR(H12/C12,0) -> 2202.0379 | K12: =J12-2500 -> -297.96215 | L12: =IFERROR(SUMIFS(DATA!$O$2:$O$8855,DATA!$E$2:$E$8855,$A12)/C12,0) -> 0.20621469 | M12: =C12-SUMIFS(DATA!$O$2:$O$8855,DATA!$E$2:$E$8855,$A12) -> 281 | N12: =IFERROR(H12/SUMIFS(DATA!$J$2:$J$8855,DATA!$E$2:$E$8855,$A12),0) -> 0.067466964 | O12: =IFERROR(H12/F12,0) -> 1.5615725 | P12: =IFERROR(SUMIFS(DATA!$J$2:$J$8855,DATA!$E$2:$E$8855,$A12)/F12,0) -> 23.145736 | Q12: =IFERROR(AVERAGEIFS(DATA!$P$2:$P$8855,DATA!$E$2:$E$8855,$A12),0) -> 0.69919412 | R12: =IFERROR(AVERAGEIFS(DATA!$Q$2:$Q$8855,DATA!$E$2:$E$8855,$A12),0) -> 0.13076189 | S12: 11.8 | T12: =IFERROR(AVERAGEIFS(DATA!$R$2:$R$8855,DATA!$E$2:$E$8855,$A12),0) -> 76.573446 | U12: =IFERROR(AVERAGEIFS(DATA!$S$2:$S$8855,DATA!$E$2:$E$8855,$A12),0) -> 10.5
A13: NOBLE | B13: RANKED | C13: =COUNTIFS(DATA!$E$2:$E$8855,$A13) -> 245 | D13: 8 | E13: 22 | F13: =SUMIFS(DATA!$H$2:$H$8855,DATA!$E$2:$E$8855,$A13) -> 235943 | G13: =IFERROR(F13/C13,0) -> 963.03265 | H13: =SUMIFS(DATA!$L$2:$L$8855,DATA!$E$2:$E$8855,$A13) -> 656632.14 | I13: =H13/SUM($H$5:$H$29) -> 0.028993366 | J13: =IFERROR(H13/C13,0) -> 2680.1312 | K13: =J13-2500 -> 180.13118 | L13: =IFERROR(SUMIFS(DATA!$O$2:$O$8855,DATA!$E$2:$E$8855,$A13)/C13,0) -> 0.59591837 | M13: =C13-SUMIFS(DATA!$O$2:$O$8855,DATA!$E$2:$E$8855,$A13) -> 99 | N13: =IFERROR(H13/SUMIFS(DATA!$J$2:$J$8855,DATA!$E$2:$E$8855,$A13),0) -> 0.11808952 | O13: =IFERROR(H13/F13,0) -> 2.7830117 | P13: =IFERROR(SUMIFS(DATA!$J$2:$J$8855,DATA!$E$2:$E$8855,$A13)/F13,0) -> 23.566966 | Q13: =IFERROR(AVERAGEIFS(DATA!$P$2:$P$8855,DATA!$E$2:$E$8855,$A13),0) -> 0.54897053 | R13: =IFERROR(AVERAGEIFS(DATA!$Q$2:$Q$8855,DATA!$E$2:$E$8855,$A13),0) -> 0.17506951 | S13: 6.12 | T13: =IFERROR(AVERAGEIFS(DATA!$R$2:$R$8855,DATA!$E$2:$E$8855,$A13),0) -> 73.244898 | U13: =IFERROR(AVERAGEIFS(DATA!$S$2:$S$8855,DATA!$E$2:$E$8855,$A13),0) -> 9.5020408
A14: KMART | B14: RANKED | C14: =COUNTIFS(DATA!$E$2:$E$8855,$A14) -> 292 | D14: 9 | E14: 4 | F14: =SUMIFS(DATA!$H$2:$H$8855,DATA!$E$2:$E$8855,$A14) -> 610430 | G14: =IFERROR(F14/C14,0) -> 2090.5137 | H14: =SUMIFS(DATA!$L$2:$L$8855,DATA!$E$2:$E$8855,$A14) -> 646838 | I14: =H14/SUM($H$5:$H$29) -> 0.028560909 | J14: =IFERROR(H14/C14,0) -> 2215.1986 | K14: =J14-2500 -> -284.80137 | L14: =IFERROR(SUMIFS(DATA!$O$2:$O$8855,DATA!$E$2:$E$8855,$A14)/C14,0) -> 0.26712329 | M14: =C14-SUMIFS(DATA!$O$2:$O$8855,DATA!$E$2:$E$8855,$A14) -> 214 | N14: =IFERROR(H14/SUMIFS(DATA!$J$2:$J$8855,DATA!$E$2:$E$8855,$A14),0) -> 0.070957827 | O14: =IFERROR(H14/F14,0) -> 1.0596432 | P14: =IFERROR(SUMIFS(DATA!$J$2:$J$8855,DATA!$E$2:$E$8855,$A14)/F14,0) -> 14.933422 | Q14: =IFERROR(AVERAGEIFS(DATA!$P$2:$P$8855,DATA!$E$2:$E$8855,$A14),0) -> 0.68418504 | R14: =IFERROR(AVERAGEIFS(DATA!$Q$2:$Q$8855,DATA!$E$2:$E$8855,$A14),0) -> 0.12733715 | S14: 15.37 | T14: =IFERROR(AVERAGEIFS(DATA!$R$2:$R$8855,DATA!$E$2:$E$8855,$A14),0) -> 75.027397 | U14: =IFERROR(AVERAGEIFS(DATA!$S$2:$S$8855,DATA!$E$2:$E$8855,$A14),0) -> 10.421233
A15: NEW YORKER | B15: RANKED | C15: =COUNTIFS(DATA!$E$2:$E$8855,$A15) -> 107 | D15: 6 | E15: 4 | F15: =SUMIFS(DATA!$H$2:$H$8855,DATA!$E$2:$E$8855,$A15) -> 162225 | G15: =IFERROR(F15/C15,0) -> 1516.1215 | H15: =SUMIFS(DATA!$L$2:$L$8855,DATA!$E$2:$E$8855,$A15) -> 242478.4 | I15: =H15/SUM($H$5:$H$29) -> 0.01070655 | J15: =IFERROR(H15/C15,0) -> 2266.1533 | K15: =J15-2500 -> -233.84673 | L15: =IFERROR(SUMIFS(DATA!$O$2:$O$8855,DATA!$E$2:$E$8855,$A15)/C15,0) -> 0.30841121 | M15: =C15-SUMIFS(DATA!$O$2:$O$8855,DATA!$E$2:$E$8855,$A15) -> 74 | N15: =IFERROR(H15/SUMIFS(DATA!$J$2:$J$8855,DATA!$E$2:$E$8855,$A15),0) -> 0.072236856 | O15: =IFERROR(H15/F15,0) -> 1.4947043 | P15: =IFERROR(SUMIFS(DATA!$J$2:$J$8855,DATA!$E$2:$E$8855,$A15)/F15,0) -> 20.691713 | Q15: =IFERROR(AVERAGEIFS(DATA!$P$2:$P$8855,DATA!$E$2:$E$8855,$A15),0) -> 0.67993671 | R15: =IFERROR(AVERAGEIFS(DATA!$Q$2:$Q$8855,DATA!$E$2:$E$8855,$A15),0) -> 0.12256427 | S15: 13.38 | T15: =IFERROR(AVERAGEIFS(DATA!$R$2:$R$8855,DATA!$E$2:$E$8855,$A15),0) -> 73.925234 | U15: =IFERROR(AVERAGEIFS(DATA!$S$2:$S$8855,DATA!$E$2:$E$8855,$A15),0) -> 10.588785
A16: NEXT | B16: RANKED | C16: =COUNTIFS(DATA!$E$2:$E$8855,$A16) -> 288 | D16: 8 | E16: 55 | F16: =SUMIFS(DATA!$H$2:$H$8855,DATA!$E$2:$E$8855,$A16) -> 442016 | G16: =IFERROR(F16/C16,0) -> 1534.7778 | H16: =SUMIFS(DATA!$L$2:$L$8855,DATA!$E$2:$E$8855,$A16) -> 611578.6 | I16: =H16/SUM($H$5:$H$29) -> 0.027004043 | J16: =IFERROR(H16/C16,0) -> 2123.5368 | K16: =J16-2500 -> -376.46319 | L16: =IFERROR(SUMIFS(DATA!$O$2:$O$8855,DATA!$E$2:$E$8855,$A16)/C16,0) -> 0.28819444 | M16: =C16-SUMIFS(DATA!$O$2:$O$8855,DATA!$E$2:$E$8855,$A16) -> 205 | N16: =IFERROR(H16/SUMIFS(DATA!$J$2:$J$8855,DATA!$E$2:$E$8855,$A16),0) -> 0.081129594 | O16: =IFERROR(H16/F16,0) -> 1.3836119 | P16: =IFERROR(SUMIFS(DATA!$J$2:$J$8855,DATA!$E$2:$E$8855,$A16)/F16,0) -> 17.054343 | Q16: =IFERROR(AVERAGEIFS(DATA!$P$2:$P$8855,DATA!$E$2:$E$8855,$A16),0) -> 0.6126628 | R16: =IFERROR(AVERAGEIFS(DATA!$Q$2:$Q$8855,DATA!$E$2:$E$8855,$A16),0) -> 0.14080806 | S16: 4.5 | T16: =IFERROR(AVERAGEIFS(DATA!$R$2:$R$8855,DATA!$E$2:$E$8855,$A16),0) -> 71.510417 | U16: =IFERROR(AVERAGEIFS(DATA!$S$2:$S$8855,DATA!$E$2:$E$8855,$A16),0) -> 10.378472
... A29: SSL | B29: TRIAL | C29: =COUNTIFS(DATA!$E$2:$E$8855,$A29) -> 4 | D29: 4 | E29: 1 | F29: =SUMIFS(DATA!$H$2:$H$8855,DATA!$E$2:$E$8855,$A29) -> 4780 | G29: =IFERROR(F29/C29,0) -> 1195 | H29: =SUMIFS(DATA!$L$2:$L$8855,DATA!$E$2:$E$8855,$A29) -> 0 | I29: =H29/SUM($H$5:$H$29) -> 0 | J29: =IFERROR(H29/C29,0) -> 0 | K29: =J29-2500 -> -2500 | L29: =IFERROR(SUMIFS(DATA!$O$2:$O$8855,DATA!$E$2:$E$8855,$A29)/C29,0) -> 0 | M29: =C29-SUMIFS(DATA!$O$2:$O$8855,DATA!$E$2:$E$8855,$A29) -> 4 | N29: =IFERROR(H29/SUMIFS(DATA!$J$2:$J$8855,DATA!$E$2:$E$8855,$A29),0) -> 0 | O29: =IFERROR(H29/F29,0) -> 0 | P29: =IFERROR(SUMIFS(DATA!$J$2:$J$8855,DATA!$E$2:$E$8855,$A29)/F29,0) -> 19.014916 | Q29: =IFERROR(AVERAGEIFS(DATA!$P$2:$P$8855,DATA!$E$2:$E$8855,$A29),0) -> 0.4209 | R29: =IFERROR(AVERAGEIFS(DATA!$Q$2:$Q$8855,DATA!$E$2:$E$8855,$A29),0) -> 0.122425 | S29: 1 | T29: =IFERROR(AVERAGEIFS(DATA!$R$2:$R$8855,DATA!$E$2:$E$8855,$A29),0) -> 74 | U29: =IFERROR(AVERAGEIFS(DATA!$S$2:$S$8855,DATA!$E$2:$E$8855,$A29),0) -> 10.5
A30: FACTORY TOTAL | C30: =SUM(C5:C29) -> 8854 | F30: =SUM(F5:F29) -> 13465130 | G30: =F30/C30 -> 1520.7963 | H30: =SUM(H5:H29) -> 22647668 | I30: 1 | J30: =H30/C30 -> 2557.9024 | K30: =J30-2500 -> 57.902449 | L30: =SUM(DATA!$O$2:$O$8855)/C30 -> 0.5286876 | M30: =C30-SUM(DATA!$O$2:$O$8855) -> 4173 | N30: =H30/SUM(DATA!$J$2:$J$8855) -> 0.08356707 | O30: =H30/F30 -> 1.6819494 | P30: =SUM(DATA!$J$2:$J$8855)/F30 -> 20.12694 | Q30: =AVERAGE(DATA!$P$2:$P$8855) -> 0.69638952 | R30: =AVERAGE(DATA!$Q$2:$Q$8855) -> 0.13167184

Sheet RANKING
A1: Buyer ranking — six standards, scored out of 100
A2: Yellow cells are inputs. Change a standard or a weight and every score, grade and rank recalculates. Buyers under 40 line-days are listed as TRIAL and not ranked.
A4: STANDARDS (score = actual ÷ standard × 100, capped at 100)
A5: Benchmark $/line-day | C5: Value: share of earned | E5: Price: CM$/SMV min | G5: Efficiency | I5: Quality: DHU | K5: Run stability: days
A6: 2500 | C6: 0.1 | E6: 0.0843 | G6: 0.8 | I6: 0.1 | K6: 10
A7: WEIGHT | M7: TOTAL
A8: 0.3 | C8: 0.2 | E8: 0.2 | G8: 0.15 | I8: 0.1 | K8: 0.05 | M8: =SUM(A8,C8,E8,G8,I8,K8) -> 1
A10: RANK | B10: BUYER | C10: GRADE | D10: SCORE | E10: LINE-DAYS | F10: EARNED $ | G10: $/LINE-DAY | H10: HIT RATE | I10: CM$/MIN | J10: CM $/PC | K10: SMV | L10: EFFICIENCY | M10: DHU % | N10: RUN DAYS | O10: S:BENCH | P10: S:VALUE | Q10: S:PRICE | R10: S:EFF | S10: S:QUAL | T10: S:RUN | U10: RANK BY $ | V10: MOVE
A11: =RANK(D11,$D$11:$D$27) -> 1 | B11: ZARA | C11: =IF(D11>=85,"A",IF(D11>=75,"B",IF(D11>=65,"C","D"))) -> A | D11: =O11*$A$8+P11*$C$8+Q11*$E$8+R11*$G$8+S11*$I$8+T11*$K$8 -> 96.193225 | E11: ='BUYER KPI'!C5 -> 2451 | F11: ='BUYER KPI'!H5 -> 7120480 | G11: ='BUYER KPI'!J5 -> 2905.1326 | H11: ='BUYER KPI'!L5 -> 0.73602611 | I11: ='BUYER KPI'!N5 -> 0.087361825 | J11: ='BUYER KPI'!O5 -> 1.8930735 | K11: ='BUYER KPI'!P5 -> 21.669345 | L11: ='BUYER KPI'!Q5 -> 0.74457829 | M11: ='BUYER KPI'!R5 -> 0.13826704 | N11: ='BUYER KPI'!S5 -> 10.94 | O11: =MIN(100,G11/$A$6*100) -> 100 | P11: =MIN(100,'BUYER KPI'!I5/$C$6*100) -> 100 | Q11: =MIN(100,I11/$E$6*100) -> 100 | R11: =MIN(100,L11/$G$6*100) -> 93.072286 | S11: =IFERROR(MIN(100,$I$6/M11*100),100) -> 72.323817 | T11: =MIN(100,N11/$K$6*100) -> 100 | U11: =RANK(F11,$F$11:$F$27) -> 1 | V11: =U11-A11 -> 0
A12: =RANK(D12,$D$11:$D$27) -> 2 | B12: GAP | C12: =IF(D12>=85,"A",IF(D12>=75,"B",IF(D12>=65,"C","D"))) -> A | D12: =O12*$A$8+P12*$C$8+Q12*$E$8+R12*$G$8+S12*$I$8+T12*$K$8 -> 94.332965 | E12: ='BUYER KPI'!C6 -> 737 | F12: ='BUYER KPI'!H6 -> 2300232.4 | G12: ='BUYER KPI'!J6 -> 3121.0752 | H12: ='BUYER KPI'!L6 -> 0.79104478 | I12: ='BUYER KPI'!N6 -> 0.098573888 | J12: ='BUYER KPI'!O6 -> 1.8752883 | K12: ='BUYER KPI'!P6 -> 19.024189 | L12: ='BUYER KPI'!Q6 -> 0.74508733 | M12: ='BUYER KPI'!R6 -> 0.12840963 | N12: ='BUYER KPI'!S6 -> 5.15 | O12: =MIN(100,G12/$A$6*100) -> 100 | P12: =MIN(100,'BUYER KPI'!I6/$C$6*100) -> 100 | Q12: =MIN(100,I12/$E$6*100) -> 100 | R12: =MIN(100,L12/$G$6*100) -> 93.135916 | S12: =IFERROR(MIN(100,$I$6/M12*100),100) -> 77.87578 | T12: =MIN(100,N12/$K$6*100) -> 51.5 | U12: =RANK(F12,$F$11:$F$27) -> 3 | V12: =U12-A12 -> 1
A13: =RANK(D13,$D$11:$D$27) -> 3 | B13: OJG | C13: =IF(D13>=85,"A",IF(D13>=75,"B",IF(D13>=65,"C","D"))) -> A | D13: =O13*$A$8+P13*$C$8+Q13*$E$8+R13*$G$8+S13*$I$8+T13*$K$8 -> 94.168343 | E13: ='BUYER KPI'!C7 -> 2515 | F13: ='BUYER KPI'!H7 -> 6082386.7 | G13: ='BUYER KPI'!J7 -> 2418.444 | H13: ='BUYER KPI'!L7 -> 0.49105368 | I13: ='BUYER KPI'!N7 -> 0.079700162 | J13: ='BUYER KPI'!O7 -> 1.5268635 | K13: ='BUYER KPI'!P7 -> 19.157596 | L13: ='BUYER KPI'!Q7 -> 0.70269445 | M13: ='BUYER KPI'!R7 -> 0.12356669 | N13: ='BUYER KPI'!S7 -> 9.94 | O13: =MIN(100,G13/$A$6*100) -> 96.737761 | P13: =MIN(100,'BUYER KPI'!I7/$C$6*100) -> 100 | Q13: =MIN(100,I13/$E$6*100) -> 94.54349 | R13: =MIN(100,L13/$G$6*100) -> 87.836807 | S13: =IFERROR(MIN(100,$I$6/M13*100),100) -> 80.92796 | T13: =MIN(100,N13/$K$6*100) -> 99.4 | U13: =RANK(F13,$F$11:$F$27) -> 2 | V13: =U13-A13 -> -1
A14: =RANK(D14,$D$11:$D$27) -> 4 | B14: TARGET | C14: =IF(D14>=85,"A",IF(D14>=75,"B",IF(D14>=65,"C","D"))) -> B | D14: =O14*$A$8+P14*$C$8+Q14*$E$8+R14*$G$8+S14*$I$8+T14*$K$8 -> 78.502116 | E14: ='BUYER KPI'!C8 -> 596 | F14: ='BUYER KPI'!H8 -> 1313095.2 | G14: ='BUYER KPI'!J8 -> 2203.1799 | H14: ='BUYER KPI'!L8 -> 0.31040268 | I14: ='BUYER KPI'!N8 -> 0.075825716 | J14: ='BUYER KPI'!O8 -> 1.6453363 | K14: ='BUYER KPI'!P8 -> 21.698922 | L14: ='BUYER KPI'!Q8 -> 0.66951562 | M14: ='BUYER KPI'!R8 -> 0.11709338 | N14: ='BUYER KPI'!S8 -> 2.77 | O14: =MIN(100,G14/$A$6*100) -> 88.127195 | P14: =MIN(100,'BUYER KPI'!I8/$C$6*100) -> 57.979267 | Q14: =MIN(100,I14/$E$6*100) -> 89.947469 | R14: =MIN(100,L14/$G$6*100) -> 83.689453 | S14: =IFERROR(MIN(100,$I$6/M14*100),100) -> 85.401923 | T14: =MIN(100,N14/$K$6*100) -> 27.7 | U14: =RANK(F14,$F$11:$F$27) -> 4 | V14: =U14-A14 -> 0
A15: =RANK(D15,$D$11:$D$27) -> 5 | B15: EXPRESS | C15: =IF(D15>=85,"A",IF(D15>=75,"B",IF(D15>=65,"C","D"))) -> B | D15: =O15*$A$8+P15*$C$8+Q15*$E$8+R15*$G$8+S15*$I$8+T15*$K$8 -> 77.446476 | E15: ='BUYER KPI'!C9 -> 258 | F15: ='BUYER KPI'!H9 -> 807715.5 | G15: ='BUYER KPI'!J9 -> 3130.6802 | H15: ='BUYER KPI'!L9 -> 0.7751938 | I15: ='BUYER KPI'!N9 -> 0.11590567 | J15: ='BUYER KPI'!O9 -> 2.4604844 | K15: ='BUYER KPI'!P9 -> 21.228334 | L15: ='BUYER KPI'!Q9 -> 0.64701564 | M15: ='BUYER KPI'!R9 -> 0.14220599 | N15: ='BUYER KPI'!S9 -> 2.3 | O15: =MIN(100,G15/$A$6*100) -> 100 | P15: =MIN(100,'BUYER KPI'!I9/$C$6*100) -> 35.6644 | Q15: =MIN(100,I15/$E$6*100) -> 100 | R15: =MIN(100,L15/$G$6*100) -> 80.876955 | S15: =IFERROR(MIN(100,$I$6/M15*100),100) -> 70.320525 | T15: =MIN(100,N15/$K$6*100) -> 23 | U15: =RANK(F15,$F$11:$F$27) -> 5 | V15: =U15-A15 -> 0
A16: =RANK(D16,$D$11:$D$27) -> 6 | B16: AERO | C16: =IF(D16>=85,"A",IF(D16>=75,"B",IF(D16>=65,"C","D"))) -> B | D16: =O16*$A$8+P16*$C$8+Q16*$E$8+R16*$G$8+S16*$I$8+T16*$K$8 -> 76.410112 | E16: ='BUYER KPI'!C10 -> 140 | F16: ='BUYER KPI'!H10 -> 357181.6 | G16: ='BUYER KPI'!J10 -> 2551.2971 | H16: ='BUYER KPI'!L10 -> 0.64285714 | I16: ='BUYER KPI'!N10 -> 0.097944429 | J16: ='BUYER KPI'!O10 -> 1.6241876 | K16: ='BUYER KPI'!P10 -> 16.582746 | L16: ='BUYER KPI'!Q10 -> 0.62616115 | M16: ='BUYER KPI'!R10 -> 0.12770831 | N16: ='BUYER KPI'!S10 -> 7.37 | O16: =MIN(100,G16/$A$6*100) -> 100 | P16: =MIN(100,'BUYER KPI'!I10/$C$6*100) -> 15.771231 | Q16: =MIN(100,I16/$E$6*100) -> 100 | R16: =MIN(100,L16/$G$6*100) -> 78.270144 | S16: =IFERROR(MIN(100,$I$6/M16*100),100) -> 78.303441 | T16: =MIN(100,N16/$K$6*100) -> 73.7 | U16: =RANK(F16,$F$11:$F$27) -> 12 | V16: =U16-A16 -> 6
A17: =RANK(D17,$D$11:$D$27) -> 7 | B17: IMPLUSE | C17: =IF(D17>=85,"A",IF(D17>=75,"B",IF(D17>=65,"C","D"))) -> B | D17: =O17*$A$8+P17*$C$8+Q17*$E$8+R17*$G$8+S17*$I$8+T17*$K$8 -> 75.683266 | E17: ='BUYER KPI'!C11 -> 180 | F17: ='BUYER KPI'!H11 -> 412264 | G17: ='BUYER KPI'!J11 -> 2290.3556 | H17: ='BUYER KPI'!L11 -> 0.48888889 | I17: ='BUYER KPI'!N11 -> 0.08127649 | J17: ='BUYER KPI'!O11 -> 1.6357735 | K17: ='BUYER KPI'!P11 -> 20.126035 | L17: ='BUYER KPI'!Q11 -> 0.62849872 | M17: ='BUYER KPI'!R11 -> 0.10862133 | N17: ='BUYER KPI'!S11 -> 8.57 | O17: =MIN(100,G17/$A$6*100) -> 91.614222 | P17: =MIN(100,'BUYER KPI'!I11/$C$6*100) -> 18.203375 | Q17: =MIN(100,I17/$E$6*100) -> 96.413393 | R17: =MIN(100,L17/$G$6*100) -> 78.562341 | S17: =IFERROR(MIN(100,$I$6/M17*100),100) -> 92.062946 | T17: =MIN(100,N17/$K$6*100) -> 85.7 | U17: =RANK(F17,$F$11:$F$27) -> 11 | V17: =U17-A17 -> 4
A18: =RANK(D18,$D$11:$D$27) -> 8 | B18: SOLAMODA | C18: =IF(D18>=85,"A",IF(D18>=75,"B",IF(D18>=65,"C","D"))) -> B | D18: =O18*$A$8+P18*$C$8+Q18*$E$8+R18*$G$8+S18*$I$8+T18*$K$8 -> 75.072129 | E18: ='BUYER KPI'!C12 -> 354 | F18: ='BUYER KPI'!H12 -> 779521.4 | G18: ='BUYER KPI'!J12 -> 2202.0379 | H18: ='BUYER KPI'!L12 -> 0.20621469 | I18: ='BUYER KPI'!N12 -> 0.067466964 | J18: ='BUYER KPI'!O12 -> 1.5615725 | K18: ='BUYER KPI'!P12 -> 23.145736 | L18: ='BUYER KPI'!Q12 -> 0.69919412 | M18: ='BUYER KPI'!R12 -> 0.13076189 | N18: ='BUYER KPI'!S12 -> 11.8 | O18: =MIN(100,G18/$A$6*100) -> 88.081514 | P18: =MIN(100,'BUYER KPI'!I12/$C$6*100) -> 34.419499 | Q18: =MIN(100,I18/$E$6*100) -> 80.031986 | R18: =MIN(100,L18/$G$6*100) -> 87.399265 | S18: =IFERROR(MIN(100,$I$6/M18*100),100) -> 76.474882 | T18: =MIN(100,N18/$K$6*100) -> 100 | U18: =RANK(F18,$F$11:$F$27) -> 6 | V18: =U18-A18 -> -2
A19: =RANK(D19,$D$11:$D$27) -> 9 | B19: NOBLE | C19: =IF(D19>=85,"A",IF(D19>=75,"B",IF(D19>=65,"C","D"))) -> C | D19: =O19*$A$8+P19*$C$8+Q19*$E$8+R19*$G$8+S19*$I$8+T19*$K$8 -> 74.863887 | E19: ='BUYER KPI'!C13 -> 245 | F19: ='BUYER KPI'!H13 -> 656632.14 | G19: ='BUYER KPI'!J13 -> 2680.1312 | H19: ='BUYER KPI'!L13 -> 0.59591837 | I19: ='BUYER KPI'!N13 -> 0.11808952 | J19: ='BUYER KPI'!O13 -> 2.7830117 | K19: ='BUYER KPI'!P13 -> 23.566966 | L19: ='BUYER KPI'!Q13 -> 0.54897053 | M19: ='BUYER KPI'!R13 -> 0.17506951 | N19: ='BUYER KPI'!S13 -> 6.12 | O19: =MIN(100,G19/$A$6*100) -> 100 | P19: =MIN(100,'BUYER KPI'!I13/$C$6*100) -> 28.993366 | Q19: =MIN(100,I19/$E$6*100) -> 100 | R19: =MIN(100,L19/$G$6*100) -> 68.621316 | S19: =IFERROR(MIN(100,$I$6/M19*100),100) -> 57.120168 | T19: =MIN(100,N19/$K$6*100) -> 61.2 | U19: =RANK(F19,$F$11:$F$27) -> 7 | V19: =U19-A19 -> -2
A20: =RANK(D20,$D$11:$D$27) -> 10 | B20: KMART | C20: =IF(D20>=85,"A",IF(D20>=75,"B",IF(D20>=65,"C","D"))) -> C | D20: =O20*$A$8+P20*$C$8+Q20*$E$8+R20*$G$8+S20*$I$8+T20*$K$8 -> 74.8108 | E20: ='BUYER KPI'!C14 -> 292 | F20: ='BUYER KPI'!H14 -> 646838 | G20: ='BUYER KPI'!J14 -> 2215.1986 | H20: ='BUYER KPI'!L14 -> 0.26712329 | I20: ='BUYER KPI'!N14 -> 0.070957827 | J20: ='BUYER KPI'!O14 -> 1.0596432 | K20: ='BUYER KPI'!P14 -> 14.933422 | L20: ='BUYER KPI'!Q14 -> 0.68418504 | M20: ='BUYER KPI'!R14 -> 0.12733715 | N20: ='BUYER KPI'!S14 -> 15.37 | O20: =MIN(100,G20/$A$6*100) -> 88.607945 | P20: =MIN(100,'BUYER KPI'!I14/$C$6*100) -> 28.560909 | Q20: =MIN(100,I20/$E$6*100) -> 84.172986 | R20: =MIN(100,L20/$G$6*100) -> 85.52313 | S20: =IFERROR(MIN(100,$I$6/M20*100),100) -> 78.531679 | T20: =MIN(100,N20/$K$6*100) -> 100 | U20: =RANK(F20,$F$11:$F$27) -> 8 | V20: =U20-A20 -> -2
A21: =RANK(D21,$D$11:$D$27) -> 11 | B21: NEW YORKER | C21: =IF(D21>=85,"A",IF(D21>=75,"B",IF(D21>=65,"C","D"))) -> C | D21: =O21*$A$8+P21*$C$8+Q21*$E$8+R21*$G$8+S21*$I$8+T21*$K$8 -> 72.380991 | E21: ='BUYER KPI'!C15 -> 107 | F21: ='BUYER KPI'!H15 -> 242478.4 | G21: ='BUYER KPI'!J15 -> 2266.1533 | H21: ='BUYER KPI'!L15 -> 0.30841121 | I21: ='BUYER KPI'!N15 -> 0.072236856 | J21: ='BUYER KPI'!O15 -> 1.4947043 | K21: ='BUYER KPI'!P15 -> 20.691713 | L21: ='BUYER KPI'!Q15 -> 0.67993671 | M21: ='BUYER KPI'!R15 -> 0.12256427 | N21: ='BUYER KPI'!S15 -> 13.38 | O21: =MIN(100,G21/$A$6*100) -> 90.646131 | P21: =MIN(100,'BUYER KPI'!I15/$C$6*100) -> 10.70655 | Q21: =MIN(100,I21/$E$6*100) -> 85.69022 | R21: =MIN(100,L21/$G$6*100) -> 84.992089 | S21: =IFERROR(MIN(100,$I$6/M21*100),100) -> 81.589845 | T21: =MIN(100,N21/$K$6*100) -> 100 | U21: =RANK(F21,$F$11:$F$27) -> 14 | V21: =U21-A21 -> 3
A22: =RANK(D22,$D$11:$D$27) -> 12 | B22: NEXT | C22: =IF(D22>=85,"A",IF(D22>=75,"B",IF(D22>=65,"C","D"))) -> C | D22: =O22*$A$8+P22*$C$8+Q22*$E$8+R22*$G$8+S22*$I$8+T22*$K$8 -> 70.970372 | E22: ='BUYER KPI'!C16 -> 288 | F22: ='BUYER KPI'!H16 -> 611578.6 | G22: ='BUYER KPI'!J16 -> 2123.5368 | H22: ='BUYER KPI'!L16 -> 0.28819444 | I22: ='BUYER KPI'!N16 -> 0.081129594 | J22: ='BUYER KPI'!O16 -> 1.3836119 | K22: ='BUYER KPI'!P16 -> 17.054343 | L22: ='BUYER KPI'!Q16 -> 0.6126628 | M22: ='BUYER KPI'!R16 -> 0.14080806 | N22: ='BUYER KPI'!S16 -> 4.5 | O22: =MIN(100,G22/$A$6*100) -> 84.941472 | P22: =MIN(100,'BUYER KPI'!I16/$C$6*100) -> 27.004043 | Q22: =MIN(100,I22/$E$6*100) -> 96.239139 | R22: =MIN(100,L22/$G$6*100) -> 76.58285 | S22: =IFERROR(MIN(100,$I$6/M22*100),100) -> 71.01866 | T22: =MIN(100,N22/$K$6*100) -> 45 | U22: =RANK(F22,$F$11:$F$27) -> 9 | V22: =U22-A22 -> -3
... A27: =RANK(D27,$D$11:$D$27) -> 17 | B27: CARRE FOUR | C27: =IF(D27>=85,"A",IF(D27>=75,"B",IF(D27>=65,"C","D"))) -> D | D27: =O27*$A$8+P27*$C$8+Q27*$E$8+R27*$G$8+S27*$I$8+T27*$K$8 -> 60.069199 | E27: ='BUYER KPI'!C21 -> 113 | F27: ='BUYER KPI'!H21 -> 201103.98 | G27: ='BUYER KPI'!J21 -> 1779.6812 | H27: ='BUYER KPI'!L21 -> 0.026548673 | I27: ='BUYER KPI'!N21 -> 0.077204943 | J27: ='BUYER KPI'!O21 -> 2.0198463 | K27: ='BUYER KPI'!P21 -> 26.162137 | L27: ='BUYER KPI'!Q21 -> 0.50142185 | M27: ='BUYER KPI'!R21 -> 0.18336119 | N27: ='BUYER KPI'!S21 -> 7.53 | O27: =MIN(100,G27/$A$6*100) -> 71.18725 | P27: =MIN(100,'BUYER KPI'!I21/$C$6*100) -> 8.879677 | Q27: =MIN(100,I27/$E$6*100) -> 91.583563 | R27: =MIN(100,L27/$G$6*100) -> 62.677731 | S27: =IFERROR(MIN(100,$I$6/M27*100),100) -> 54.537169 | T27: =MIN(100,N27/$K$6*100) -> 75.3 | U27: =RANK(F27,$F$11:$F$27) -> 15 | V27: =U27-A27 -> -2
B29: TRIAL — under 40 line-days, scored but not ranked
B30: LUCKY | E30: ='BUYER KPI'!C22 -> 18 | F30: ='BUYER KPI'!H22 -> 34620 | G30: ='BUYER KPI'!J22 -> 1923.3333 | H30: ='BUYER KPI'!L22 -> 0.27777778 | I30: ='BUYER KPI'!N22 -> 0.075670841 | L30: ='BUYER KPI'!Q22 -> 0.48671667
B31: PULL & BEAR | E31: ='BUYER KPI'!C23 -> 17 | F31: ='BUYER KPI'!H23 -> 29536.8 | G31: ='BUYER KPI'!J23 -> 1737.4588 | H31: ='BUYER KPI'!L23 -> 0 | I31: ='BUYER KPI'!N23 -> 0.077406147 | L31: ='BUYER KPI'!Q23 -> 0.5167
B32: FAKE GODS | E32: ='BUYER KPI'!C24 -> 9 | F32: ='BUYER KPI'!H24 -> 27024 | G32: ='BUYER KPI'!J24 -> 3002.6667 | H32: ='BUYER KPI'!L24 -> 0.66666667 | I32: ='BUYER KPI'!N24 -> 0.18830744 | L32: ='BUYER KPI'!Q24 -> 0.39246667
B33: JOULES | E33: ='BUYER KPI'!C25 -> 6 | F33: ='BUYER KPI'!H25 -> 17560 | G33: ='BUYER KPI'!J25 -> 2926.6667 | H33: ='BUYER KPI'!L25 -> 0.5 | I33: ='BUYER KPI'!N25 -> 0.15043004 | L33: ='BUYER KPI'!Q25 -> 0.39728333
B34: BUSS PRO | E34: ='BUYER KPI'!C26 -> 11 | F34: ='BUYER KPI'!H26 -> 9157.5 | G34: ='BUYER KPI'!J26 -> 832.5 | H34: ='BUYER KPI'!L26 -> 0 | I34: ='BUYER KPI'!N26 -> 0.045565006 | L34: ='BUYER KPI'!Q26 -> 0.57449552
B35: CAREFOUR | E35: ='BUYER KPI'!C27 -> 4 | F35: ='BUYER KPI'!H27 -> 3685 | G35: ='BUYER KPI'!J27 -> 921.25 | H35: ='BUYER KPI'!L27 -> 0 | I35: ='BUYER KPI'!N27 -> 0.10860755 | L35: ='BUYER KPI'!Q27 -> 0.17184131
B36: CIRCULAR JEAN | E36: ='BUYER KPI'!C28 -> 3 | F36: ='BUYER KPI'!H28 -> 2707.5 | G36: ='BUYER KPI'!J28 -> 902.5 | H36: ='BUYER KPI'!L28 -> 0 | I36: ='BUYER KPI'!N28 -> 0.078206465 | L36: ='BUYER KPI'!Q28 -> 0.24383333
B37: SSL | E37: ='BUYER KPI'!C29 -> 4 | F37: ='BUYER KPI'!H29 -> 0 | G37: ='BUYER KPI'!J29 -> 0 | H37: ='BUYER KPI'!L29 -> 0 | I37: ='BUYER KPI'!N29 -> 0 | L37: ='BUYER KPI'!Q29 -> 0.4209

Sheet BENCHMARK GAP
A1: The $2,500 per line-day benchmark
A2: Shortfall = (2,500 − earned per line-day) × line-days. It is capacity value missed over the period, not a cash loss.
A4: BENCHMARK ($ per line per day) | D4: 2500
A6: BUYER | B6: TIER | C6: LINE-DAYS | D6: EARNED $ | E6: $ / LINE-DAY | F6: VS BENCHMARK | G6: HIT RATE | H6: DAYS BELOW | I6: SURPLUS / SHORTFALL $ | J6: % OF BENCHMARK
A7: ZARA | B7: ='BUYER KPI'!B5 -> RANKED | C7: ='BUYER KPI'!C5 -> 2451 | D7: ='BUYER KPI'!H5 -> 7120480 | E7: ='BUYER KPI'!J5 -> 2905.1326 | F7: =E7-$D$4 -> 405.13258 | G7: ='BUYER KPI'!L5 -> 0.73602611 | H7: ='BUYER KPI'!M5 -> 647 | I7: =F7*C7 -> 992979.95 | J7: =E7/$D$4 -> 1.162053
A8: GAP | B8: ='BUYER KPI'!B6 -> RANKED | C8: ='BUYER KPI'!C6 -> 737 | D8: ='BUYER KPI'!H6 -> 2300232.4 | E8: ='BUYER KPI'!J6 -> 3121.0752 | F8: =E8-$D$4 -> 621.07517 | G8: ='BUYER KPI'!L6 -> 0.79104478 | H8: ='BUYER KPI'!M6 -> 154 | I8: =F8*C8 -> 457732.4 | J8: =E8/$D$4 -> 1.2484301
A9: OJG | B9: ='BUYER KPI'!B7 -> RANKED | C9: ='BUYER KPI'!C7 -> 2515 | D9: ='BUYER KPI'!H7 -> 6082386.7 | E9: ='BUYER KPI'!J7 -> 2418.444 | F9: =E9-$D$4 -> -81.555977 | G9: ='BUYER KPI'!L7 -> 0.49105368 | H9: ='BUYER KPI'!M7 -> 1280 | I9: =F9*C9 -> -205113.28 | J9: =E9/$D$4 -> 0.96737761
A10: TARGET | B10: ='BUYER KPI'!B8 -> RANKED | C10: ='BUYER KPI'!C8 -> 596 | D10: ='BUYER KPI'!H8 -> 1313095.2 | E10: ='BUYER KPI'!J8 -> 2203.1799 | F10: =E10-$D$4 -> -296.82013 | G10: ='BUYER KPI'!L8 -> 0.31040268 | H10: ='BUYER KPI'!M8 -> 411 | I10: =F10*C10 -> -176904.8 | J10: =E10/$D$4 -> 0.88127195
A11: EXPRESS | B11: ='BUYER KPI'!B9 -> RANKED | C11: ='BUYER KPI'!C9 -> 258 | D11: ='BUYER KPI'!H9 -> 807715.5 | E11: ='BUYER KPI'!J9 -> 3130.6802 | F11: =E11-$D$4 -> 630.68023 | G11: ='BUYER KPI'!L9 -> 0.7751938 | H11: ='BUYER KPI'!M9 -> 58 | I11: =F11*C11 -> 162715.5 | J11: =E11/$D$4 -> 1.2522721
A12: AERO | B12: ='BUYER KPI'!B10 -> RANKED | C12: ='BUYER KPI'!C10 -> 140 | D12: ='BUYER KPI'!H10 -> 357181.6 | E12: ='BUYER KPI'!J10 -> 2551.2971 | F12: =E12-$D$4 -> 51.297143 | G12: ='BUYER KPI'!L10 -> 0.64285714 | H12: ='BUYER KPI'!M10 -> 50 | I12: =F12*C12 -> 7181.6 | J12: =E12/$D$4 -> 1.0205189
A13: IMPLUSE | B13: ='BUYER KPI'!B11 -> RANKED | C13: ='BUYER KPI'!C11 -> 180 | D13: ='BUYER KPI'!H11 -> 412264 | E13: ='BUYER KPI'!J11 -> 2290.3556 | F13: =E13-$D$4 -> -209.64444 | G13: ='BUYER KPI'!L11 -> 0.48888889 | H13: ='BUYER KPI'!M11 -> 92 | I13: =F13*C13 -> -37736 | J13: =E13/$D$4 -> 0.91614222
A14: SOLAMODA | B14: ='BUYER KPI'!B12 -> RANKED | C14: ='BUYER KPI'!C12 -> 354 | D14: ='BUYER KPI'!H12 -> 779521.4 | E14: ='BUYER KPI'!J12 -> 2202.0379 | F14: =E14-$D$4 -> -297.96215 | G14: ='BUYER KPI'!L12 -> 0.20621469 | H14: ='BUYER KPI'!M12 -> 281 | I14: =F14*C14 -> -105478.6 | J14: =E14/$D$4 -> 0.88081514
A15: NOBLE | B15: ='BUYER KPI'!B13 -> RANKED | C15: ='BUYER KPI'!C13 -> 245 | D15: ='BUYER KPI'!H13 -> 656632.14 | E15: ='BUYER KPI'!J13 -> 2680.1312 | F15: =E15-$D$4 -> 180.13118 | G15: ='BUYER KPI'!L13 -> 0.59591837 | H15: ='BUYER KPI'!M13 -> 99 | I15: =F15*C15 -> 44132.14 | J15: =E15/$D$4 -> 1.0720525
A16: KMART | B16: ='BUYER KPI'!B14 -> RANKED | C16: ='BUYER KPI'!C14 -> 292 | D16: ='BUYER KPI'!H14 -> 646838 | E16: ='BUYER KPI'!J14 -> 2215.1986 | F16: =E16-$D$4 -> -284.80137 | G16: ='BUYER KPI'!L14 -> 0.26712329 | H16: ='BUYER KPI'!M14 -> 214 | I16: =F16*C16 -> -83162 | J16: =E16/$D$4 -> 0.88607945
A17: NEW YORKER | B17: ='BUYER KPI'!B15 -> RANKED | C17: ='BUYER KPI'!C15 -> 107 | D17: ='BUYER KPI'!H15 -> 242478.4 | E17: ='BUYER KPI'!J15 -> 2266.1533 | F17: =E17-$D$4 -> -233.84673 | G17: ='BUYER KPI'!L15 -> 0.30841121 | H17: ='BUYER KPI'!M15 -> 74 | I17: =F17*C17 -> -25021.6 | J17: =E17/$D$4 -> 0.90646131
A18: NEXT | B18: ='BUYER KPI'!B16 -> RANKED | C18: ='BUYER KPI'!C16 -> 288 | D18: ='BUYER KPI'!H16 -> 611578.6 | E18: ='BUYER KPI'!J16 -> 2123.5368 | F18: =E18-$D$4 -> -376.46319 | G18: ='BUYER KPI'!L16 -> 0.28819444 | H18: ='BUYER KPI'!M16 -> 205 | I18: =F18*C18 -> -108421.4 | J18: =E18/$D$4 -> 0.84941472
... A31: SSL | B31: ='BUYER KPI'!B29 -> TRIAL | C31: ='BUYER KPI'!C29 -> 4 | D31: ='BUYER KPI'!H29 -> 0 | E31: ='BUYER KPI'!J29 -> 0 | F31: =E31-$D$4 -> -2500 | G31: ='BUYER KPI'!L29 -> 0 | H31: ='BUYER KPI'!M29 -> 4 | I31: =F31*C31 -> -10000 | J31: =E31/$D$4 -> 0
A35: WHAT $2,500 A DAY REQUIRES — a 75-operator line working 10.0 hours holds 45,000 available minutes
A36: IF EFFICIENCY IS | B36: AVAILABLE MIN | C36: EARNING MIN | D36: CM $/MIN NEEDED | E36: AT 20 SMV, CM $/PC | F36: PIECES/DAY NEEDED
A37: 0.55 | B37: =75*10*60 -> 45000 | C37: =B37*A37 -> 24750 | D37: =$D$4/C37 -> 0.1010101 | E37: =D37*20 -> 2.020202 | F37: =C37/20 -> 1237.5
A38: 0.6 | B38: =75*10*60 -> 45000 | C38: =B38*A38 -> 27000 | D38: =$D$4/C38 -> 0.092592593 | E38: =D38*20 -> 1.8518519 | F38: =C38/20 -> 1350
A39: 0.65 | B39: =75*10*60 -> 45000 | C39: =B39*A39 -> 29250 | D39: =$D$4/C39 -> 0.085470085 | E39: =D39*20 -> 1.7094017 | F39: =C39/20 -> 1462.5
A40: 0.7 | B40: =75*10*60 -> 45000 | C40: =B40*A40 -> 31500 | D40: =$D$4/C40 -> 0.079365079 | E40: =D40*20 -> 1.5873016 | F40: =C40/20 -> 1575
A41: 0.75 | B41: =75*10*60 -> 45000 | C41: =B41*A41 -> 33750 | D41: =$D$4/C41 -> 0.074074074 | E41: =D41*20 -> 1.4814815 | F41: =C41/20 -> 1687.5
A42: 0.8 | B42: =75*10*60 -> 45000 | C42: =B42*A42 -> 36000 | D42: =$D$4/C42 -> 0.069444444 | E42: =D42*20 -> 1.3888889 | F42: =C42/20 -> 1800
A43: 0.85 | B43: =75*10*60 -> 45000 | C43: =B43*A43 -> 38250 | D43: =$D$4/C43 -> 0.065359477 | E43: =D43*20 -> 1.3071895 | F43: =C43/20 -> 1912.5

Sheet IMPROVEMENT PLAN
A1: Three routes to $2,500 per line-day
A2: Each route is the earning identity solved for one variable, holding the other two at their current values. They are alternatives — hitting any one clears the benchmark. Route B assumes CM per piece is unchanged while SMV falls.
A4: Earning identity: | C4: Earned $ / line-day = CM $ per SMV minute × efficiency × operators × working hours × 60
A6: BUYER | B6: GRADE | C6: LINE-DAYS | D6: $ / LINE-DAY | E6: GAP / DAY | F6: PERIOD GAP $ | G6: NOW: CM $/PC | H6: A: CM $/PC NEEDED | I6: A: INCREASE | J6: A: % UP | K6: NOW: SMV | L6: B: SMV NEEDED | M6: B: CUT (MIN) | N6: NOW: EFF | O6: C: EFF NEEDED | P6: C: FEASIBLE? | Q6: SPLIT: EFF 75% THEN CM $/PC | R6: SPLIT: EXTRA $/PC
A7: ZARA | B7: =RANKING!C11 -> A | C7: ='BUYER KPI'!C5 -> 2451 | D7: ='BUYER KPI'!J5 -> 2905.1326 | E7: =2500-D7 -> -405.13258 | F7: =E7*C7 -> -992979.95 | G7: ='BUYER KPI'!O5 -> 1.8930735 | H7: =G7*2500/D7 -> 1.6290767 | I7: =H7-G7 -> -0.26399682 | J7: =I7/G7 -> -0.13945408 | K7: ='BUYER KPI'!P5 -> 21.669345 | L7: =K7*D7/2500 -> 25.180928 | M7: =K7-L7 -> -3.511583 | N7: ='BUYER KPI'!Q5 -> 0.74457829 | O7: =N7*2500/D7 -> 0.64074381 | P7: =IF(E7<=0,"n/a - above benchmark",IF(O7>0.85,"NO - price must carry it",IF(O7>0.78,"TIGHT - split it","YES - floor can close it"))) -> n/a - above benchmark | Q7: 1.893 | R7: =IF(E7<=0,0,MAX(0,Q7-G7)) -> 0
A8: GAP | B8: =RANKING!C12 -> A | C8: ='BUYER KPI'!C6 -> 737 | D8: ='BUYER KPI'!J6 -> 3121.0752 | E8: =2500-D8 -> -621.07517 | F8: =E8*C8 -> -457732.4 | G8: ='BUYER KPI'!O6 -> 1.8752883 | H8: =G8*2500/D8 -> 1.5021172 | I8: =H8-G8 -> -0.37317109 | J8: =I8/G8 -> -0.19899398 | K8: ='BUYER KPI'!P6 -> 19.024189 | L8: =K8*D8/2500 -> 23.75037 | M8: =K8-L8 -> -4.7261806 | N8: ='BUYER KPI'!Q6 -> 0.74508733 | O8: =N8*2500/D8 -> 0.59681943 | P8: =IF(E8<=0,"n/a - above benchmark",IF(O8>0.85,"NO - price must carry it",IF(O8>0.78,"TIGHT - split it","YES - floor can close it"))) -> n/a - above benchmark | Q8: 1.875 | R8: =IF(E8<=0,0,MAX(0,Q8-G8)) -> 0
A9: OJG | B9: =RANKING!C13 -> A | C9: ='BUYER KPI'!C7 -> 2515 | D9: ='BUYER KPI'!J7 -> 2418.444 | E9: =2500-D9 -> 81.555977 | F9: =E9*C9 -> 205113.28 | G9: ='BUYER KPI'!O7 -> 1.5268635 | H9: =G9*2500/D9 -> 1.5783532 | I9: =H9-G9 -> 0.051489654 | J9: =I9/G9 -> 0.0337225 | K9: ='BUYER KPI'!P7 -> 19.157596 | L9: =K9*D9/2500 -> 18.532629 | M9: =K9-L9 -> 0.62496658 | N9: ='BUYER KPI'!Q7 -> 0.70269445 | O9: =N9*2500/D9 -> 0.72639107 | P9: =IF(E9<=0,"n/a - above benchmark",IF(O9>0.85,"NO - price must carry it",IF(O9>0.78,"TIGHT - split it","YES - floor can close it"))) -> YES - floor can close it | Q9: 1.527 | R9: =IF(E9<=0,0,MAX(0,Q9-G9)) -> 0.00013649829
A10: TARGET | B10: =RANKING!C14 -> B | C10: ='BUYER KPI'!C8 -> 596 | D10: ='BUYER KPI'!J8 -> 2203.1799 | E10: =2500-D10 -> 296.82013 | F10: =E10*C10 -> 176904.8 | G10: ='BUYER KPI'!O8 -> 1.6453363 | H10: =G10*2500/D10 -> 1.8670018 | I10: =H10-G10 -> 0.22166549 | J10: =I10/G10 -> 0.13472351 | K10: ='BUYER KPI'!P8 -> 21.698922 | L10: =K10*D10/2500 -> 19.122651 | M10: =K10-L10 -> 2.5762708 | N10: ='BUYER KPI'!Q8 -> 0.66951562 | O10: =N10*2500/D10 -> 0.75971512 | P10: =IF(E10<=0,"n/a - above benchmark",IF(O10>0.85,"NO - price must carry it",IF(O10>0.78,"TIGHT - split it","YES - floor can close it"))) -> YES - floor can close it | Q10: 1.645 | R10: =IF(E10<=0,0,MAX(0,Q10-G10)) -> 0
A11: EXPRESS | B11: =RANKING!C15 -> B | C11: ='BUYER KPI'!C9 -> 258 | D11: ='BUYER KPI'!J9 -> 3130.6802 | E11: =2500-D11 -> -630.68023 | F11: =E11*C11 -> -162715.5 | G11: ='BUYER KPI'!O9 -> 2.4604844 | H11: =G11*2500/D11 -> 1.9648161 | I11: =H11-G11 -> -0.49566827 | J11: =I11/G11 -> -0.2014515 | K11: ='BUYER KPI'!P9 -> 21.228334 | L11: =K11*D11/2500 -> 26.58365 | M11: =K11-L11 -> -5.3553163 | N11: ='BUYER KPI'!Q9 -> 0.64701564 | O11: =N11*2500/D11 -> 0.51667337 | P11: =IF(E11<=0,"n/a - above benchmark",IF(O11>0.85,"NO - price must carry it",IF(O11>0.78,"TIGHT - split it","YES - floor can close it"))) -> n/a - above benchmark | Q11: 2.46 | R11: =IF(E11<=0,0,MAX(0,Q11-G11)) -> 0
A12: AERO | B12: =RANKING!C16 -> B | C12: ='BUYER KPI'!C10 -> 140 | D12: ='BUYER KPI'!J10 -> 2551.2971 | E12: =2500-D12 -> -51.297143 | F12: =E12*C12 -> -7181.6 | G12: ='BUYER KPI'!O10 -> 1.6241876 | H12: =G12*2500/D12 -> 1.5915312 | I12: =H12-G12 -> -0.032656402 | J12: =I12/G12 -> -0.020106299 | K12: ='BUYER KPI'!P10 -> 16.582746 | L12: =K12*D12/2500 -> 16.923005 | M12: =K12-L12 -> -0.34025901 | N12: ='BUYER KPI'!Q10 -> 0.62616115 | O12: =N12*2500/D12 -> 0.61357137 | P12: =IF(E12<=0,"n/a - above benchmark",IF(O12>0.85,"NO - price must carry it",IF(O12>0.78,"TIGHT - split it","YES - floor can close it"))) -> n/a - above benchmark | Q12: 1.624 | R12: =IF(E12<=0,0,MAX(0,Q12-G12)) -> 0
